Workbook
Name A_Pitch: '06_Road_Engine'!$D$20
Name BX_ang: '04a_Box_Dims'!$B$8
Name BX_apL: '04a_Box_Dims'!$B$7
Name BX_bat: '04a_Box_Dims'!$G$10
Name BX_blind: '04a_Box_Dims'!$B$16
Name BX_ch: '04a_Box_Dims'!$B$6
Name BX_exX: '04a_Box_Dims'!$B$18
Name BX_frb: '04a_Box_Dims'!$B$10
Name BX_Hcov: '04a_Box_Dims'!$B$5
Name BX_hemin: '04a_Box_Dims'!$G$9
Name BX_hh: '04a_Box_Dims'!$B$9
Name BX_hook: '04b_Box_Bars'!$B$4
Name BX_Lnom: '04a_Box_Dims'!$G$11
Name BX_rho: '04b_Box_Bars'!$B$6
Name BX_tdiv: '04a_Box_Dims'!$B$14
Name BX_tinc: '04a_Box_Dims'!$B$15
Name BX_tmin: '04a_Box_Dims'!$B$13
Name BX_tmin2: '04a_Box_Dims'!$G$5
Name BX_tpf: '04a_Box_Dims'!$G$8
Name BX_tpmax: '04a_Box_Dims'!$G$7
Name BX_tpmin: '04a_Box_Dims'!$G$6
Name BX_twD: '04a_Box_Dims'!$B$12
Name BX_twW: '04a_Box_Dims'!$B$11
Name BX_work: '04a_Box_Dims'!$B$17
Name BX_wwbend: '04b_Box_Bars'!$B$5
Name H_Cut: '06_Road_Engine'!$D$15
Name H_FillW: '06_Road_Engine'!$D$18
Name H_Raise: '06_Road_Engine'!$D$12
Name L_Base: '06_Road_Engine'!$D$38
Name L_Blading: '06_Road_Engine'!$D$34
Name L_Cut: '06_Road_Engine'!$D$14
Name L_DitchCL: '06_Road_Engine'!$D$21
Name L_DitchEC: '06_Road_Engine'!$D$23
Name L_DitchRE: '06_Road_Engine'!$D$22
Name L_EB: '06_Road_Engine'!$D$6
Name L_FillW: '06_Road_Engine'!$D$17
Name L_GB: '06_Road_Engine'!$D$7
Name L_Kerb: '06_Road_Engine'!$D$29
Name L_LB: '06_Road_Engine'!$D$9
Name L_Prime: '06_Road_Engine'!$D$39
Name L_Raise: '06_Road_Engine'!$D$11
Name L_Reshape: '06_Road_Engine'!$D$35
Name L_RetW: '06_Road_Engine'!$D$33
Name L_SB: '06_Road_Engine'!$D$8
Name L_Scarify: '06_Road_Engine'!$D$36
Name L_Scour: '06_Road_Engine'!$D$30
Name L_Seal1: '06_Road_Engine'!$D$40
Name L_Seal2: '06_Road_Engine'!$D$41
Name L_Subbase: '06_Road_Engine'!$D$37
Name L_TB: '06_Road_Engine'!$D$10
Name L_Town: '06_Road_Engine'!$D$5
Name L_Trap: '06_Road_Engine'!$D$28
Name L_Turn: '06_Road_Engine'!$D$32
Name L_UD45: '06_Road_Engine'!$D$24
Name L_UD60: '06_Road_Engine'!$D$25
Name L_UD75: '06_Road_Engine'!$D$26
Name L_UD90: '06_Road_Engine'!$D$27
Name P_BaseT: '00_Project'!$C$25
Name P_BinderPct: '00_Project'!$C$32
Name P_CentreLnF: '00_Project'!$C$51

Sheet README
B1: MASTER ESTIMATOR — DFR FEEDER ROAD BILL OF QUANTITIES
B2: Department of Feeder Roads. Everything is done inside this workbook: no other file, no add-in, no internet.
B4: HOW TO PRICE A ROAD
B5: 1. Agree E_Rules | C5: What the surveyor SAW is recorded on Form C; what is DONE about it is written once here, on five rows. Settle them with the design engineer before the survey starts.
B6: 2. Fill F_Road_Data | C6: The project constants. Rows marked ! are template figures nobody has confirmed for your road. Overhaul and haulage distances alone routinely move a bill by a quarter.
B7: 3. Record the survey | C7: Forms A to D, one row per stretch of road that is the same all the way along — not one row per 50 m. An 8 km road usually takes about 30 rows.
B8: 4. Type the identity | C8: Road name, code, region and district on 00_Project. The road LENGTH is measured for you from the furthest chainage on the forms.
B9: 5. Read 90_Checks | C9: Every test must read OK before the bill is issued. Then 10_BOQ is the bill and 21/22_Takeoff are the dimension papers for manual checking.
B11: THE THREE RULES THAT MAKE THE FORMS WORK
B12: Chainages are METRES | C12: 8 km is 8000, not 8. A chainage written as 8 is eight metres and the road will price at almost nothing.
B13: Later rows override earlier | C13: Lay down the general case for the whole road on line 1, then refine short stretches below it.
B14: Blank vs dash | C14: A blank cell means "unchanged". A dash - means "explicitly none here", and is how you switch something back off that an earlier row switched on.
B16: WHAT YOU MAY AND MAY NOT TYPE INTO
B17: Type here | C17: README identity block aside: 00_Project identity only, E_Rules, F_Road_Data, and Forms A, B, C, D. Every input cell is shaded yellow.
B18: Never type here | C18: 01_Stations and 02_Culverts are now FORMULAS that resolve the forms. Typing into them destroys the link and the next change to a form will not reach the bill.
B19: Never type a rate in the bill | C19: 08_Rates is the only place a price is typed. A rate typed into 10_BOQ is overwritten the moment anything upstream changes.
B21: WHAT IS NOT SETTLED — read before issuing
B22: Rates | C22: 08_Rates carries a date and a source on every line. Check they are current before the bill leaves the building.
B23: Unpriced measured items | C23: Road widening, raising, gully filling, blading, scarifying, kerb and retaining wall are measured correctly but no bill line collects them. The coverage tests on 90_Checks count them.
B24: U-culvert rates | C24: All U-culvert rate lines are blank. Any job with a U-culvert shows measured quantities pricing at zero.
B25: Box culvert flotation | C25: Every 3x3, 4x3 and 4x4 box, and 2/3x2.4, needs hold-down against buoyancy, and every box needs deepened scour protection. Neither is in the bill.
B26: Not yet parallel-run | C26: No completed project has been priced through both this workbook and the legacy set. That is the outstanding validation.

Sheet 00_Project
A1: PROJECT CONSTANTS
A2: Every global input lives here, but the VALUES now come from the input forms: the constants from F_Road_Data and the road length from the survey extent on Forms A-D. Edit those sheets, not this one. Named cells are used by name in every formula in the workbook. A red ! on F_Road_Data marks a template figure not yet confirmed for this road.
A4: Name | B4: Parameter | C4: Value | D4: Unit | E4: Note
A5: PROJECT IDENTITY
A6: P_RoadName | B6: Road name
A7: P_RoadCode | B7: Road code
A8: P_Region | B8: Region
A9: P_District | B9: District
A10: P_Programme | B10: Programme
A11: ROAD EXTENT
A12: P_Length_km | B12: Road length | C12: =MAX(MAX(A_Corridor!$B$5:$B$204),MAX(B_Drainage!$B$5:$B$204),MAX(C_Pavement!$B$5:$B$204),MAX(D_Points!$A$5:$A$204))/1000 -> 0 | D12: km | E12: Measured from the furthest chainage on Forms A-D
A13: P_Interval | B13: Station interval | C13: 50 | D13: m | E13: Fixed; matches the legacy line-diagram grid
A14: P_NStations | B14: Number of stations | C14: =ROUNDUP(P_Length_km*1000/P_Interval,0) -> 0 | D14: nr | E14: Derived
A15: CROSS-SECTION
A16: P_CW | B16: Carriageway width | C16: =F_Road_Data!$C$6 -> 7 | D16: m
A17: P_SW | B17: Shoulder width (one side) | C17: =F_Road_Data!$C$7 -> 1 | D17: m
A18: P_FW | B18: Formation width | C18: =P_CW+2*P_SW -> 9 | D18: m | E18: Derived
A19: P_ExtCW | B19: Existing carriageway width | C19: =F_Road_Data!$C$8 -> 4 | D19: m
A20: P_ClearW | B20: Clearing width | C20: =P_FW+4 -> 13 | D20: m | E20: Derived: formation + 2 m each side
A21: P_PrimeW | B21: Width for primer seal | C21: =F_Road_Data!$C$9 -> 8 | D21: m
A22: P_SealW | B22: Width of sealing | C22: =F_Road_Data!$C$10 -> 7 | D22: m
A23: PAVEMENT
A24: P_SubbaseT | B24: Sub-base thickness | C24: =F_Road_Data!$C$12 -> 0.15 | D24: m
A25: P_BaseT | B25: Base thickness | C25: =F_Road_Data!$C$13 -> 0.15 | D25: m
A26: P_OH_Sub | B26: Overhaul distance, sub-base | C26: =F_Road_Data!$C$14 -> 31 | D26: km
A27: P_OH_Base | B27: Overhaul distance, base | C27: =F_Road_Data!$C$15 -> 40 | D27: km
A28: SURFACING DESIGN RATES
A29: P_PrimeRate | B29: Primer seal binder rate | C29: =F_Road_Data!$C$17 -> 1.4 | D29: l/m²
A30: P_Seal1Rate | B30: First seal binder rate | C30: =F_Road_Data!$C$18 -> 1.3 | D30: l/m²
A31: P_Seal2Rate | B31: Second seal binder rate | C31: =F_Road_Data!$C$19 -> 1.2 | D31: l/m²
A32: P_BinderPct | B32: Binder fraction of primer | C32: =F_Road_Data!$C$20 -> 0.84 | D32: - | E32: Balance is cutter oil
A33: P_CutterPct | B33: Cutter-oil fraction of primer | C33: =F_Road_Data!$C$21 -> 0.16 | D33: -
A34: P_Chip10 | B34: 10 mm chipping coverage | C34: =F_Road_Data!$C$22 -> 120 | D34: m²/m³
A35: P_Chip14 | B35: 14 mm chipping coverage | C35: =F_Road_Data!$C$23 -> 100 | D35: m²/m³
A36: HAULAGE DISTANCES
A37: P_HaulSand | B37: Sand (fine aggregate) | C37: =F_Road_Data!$C$25 -> 15 | D37: km | E37: Legacy Proposed_Culv!J2
A38: P_HaulCoarse | B38: Coarse aggregate | C38: =F_Road_Data!$C$26 -> 25 | D38: km | E38: Legacy Proposed_Culv!J1
A39: P_HaulChip | B39: Chippings | C39: =F_Road_Data!$C$27 -> 60 | D39: km
A40: P_HaulFill | B40: Fill material | C40: =F_Road_Data!$C$28 -> 2 | D40: km
A41: AGGREGATE YIELD FACTORS
...

Sheet A_Corridor
A1: FORM A — CORRIDOR, CLEARING AND EARTHWORKS
A2: One row per stretch of road that is the same all the way along. From/To in METRES (8 km = 8000). A later row overrides an earlier one, so lay down the general case first and refine it afterwards. Blank = unchanged; a dash - = explicitly none here.
A4: From | B4: To | C4: Township Y/N | D4: Vegetation | E4: Raise road: fill (cm) | F4: Cut to widen (cm) | G4: Cut width L+R (m) | H4: Fill to widen (cm) | I4: Fill width L+R (m) | J4: Notes

Sheet B_Drainage
A1: FORM B — DRAINAGE
A2: One row per stretch. Entering a U-drain size switches that drain on. Scour checks: 1 = one side, 2 = both. Type - to cancel something an earlier row switched on.
A4: From | B4: To | C4: Ditch L | D4: Ditch R | E4: U-drain L (cm) | F4: U-drain R (cm) | G4: Trap. drain L | H4: Trap. drain R | I4: Kerb L | J4: Kerb R | K4: Scour checks | L4: Scour spacing (m) | M4: Ret. wall L | N4: Ret. wall R | O4: Notes

Sheet C_Pavement
A1: FORM C — PAVEMENT AND SURFACING
A2: Record the SURFACE CONDITION you observed and stop there. Everything to its right is filled in from E_Rules. Type in the override columns only where this stretch genuinely departs from the rule.
A4: From | B4: To | C4: Surface condition | D4: Treatment (override) | E4: Sub-base cm (ovr) | F4: Base cm (ovr) | G4: Prime (ovr) | H4: Seal 1 (ovr) | I4: Seal 2 (ovr) | J4: Notes

Sheet D_Points
A1: FORM D — POINT ITEMS
A2: Things that happen at a spot rather than over a stretch. Chainage in METRES. A PR_CULVERT row also builds the culvert schedule on 02_Culverts. Size: pipes take the diameter in mm; U- and box culverts take span x rise (900X1200, 3x3).
A4: Chainage | B4: Type | C4: Family | D4: Cells | E4: Size | F4: Length (m) | G4: Orientation | H4: Quantity | I4: Notes | K4: 0
K5: =IF(AND(UPPER(TRIM($B5))="PR_CULVERT",$A5<>"",ISNUMBER(MATCH(UPPER(TRIM($C5)),{"PC","BC","UC"},0))),MAX($K$4:K4)+1,"")
K6: =IF(AND(UPPER(TRIM($B6))="PR_CULVERT",$A6<>"",ISNUMBER(MATCH(UPPER(TRIM($C6)),{"PC","BC","UC"},0))),MAX($K$4:K5)+1,"")
K7: =IF(AND(UPPER(TRIM($B7))="PR_CULVERT",$A7<>"",ISNUMBER(MATCH(UPPER(TRIM($C7)),{"PC","BC","UC"},0))),MAX($K$4:K6)+1,"")
K8: =IF(AND(UPPER(TRIM($B8))="PR_CULVERT",$A8<>"",ISNUMBER(MATCH(UPPER(TRIM($C8)),{"PC","BC","UC"},0))),MAX($K$4:K7)+1,"")
K9: =IF(AND(UPPER(TRIM($B9))="PR_CULVERT",$A9<>"",ISNUMBER(MATCH(UPPER(TRIM($C9)),{"PC","BC","UC"},0))),MAX($K$4:K8)+1,"")
K10: =IF(AND(UPPER(TRIM($B10))="PR_CULVERT",$A10<>"",ISNUMBER(MATCH(UPPER(TRIM($C10)),{"PC","BC","UC"},0))),MAX($K$4:K9)+1,"")
K11: =IF(AND(UPPER(TRIM($B11))="PR_CULVERT",$A11<>"",ISNUMBER(MATCH(UPPER(TRIM($C11)),{"PC","BC","UC"},0))),MAX($K$4:K10)+1,"")
K12: =IF(AND(UPPER(TRIM($B12))="PR_CULVERT",$A12<>"",ISNUMBER(MATCH(UPPER(TRIM($C12)),{"PC","BC","UC"},0))),MAX($K$4:K11)+1,"")
K13: =IF(AND(UPPER(TRIM($B13))="PR_CULVERT",$A13<>"",ISNUMBER(MATCH(UPPER(TRIM($C13)),{"PC","BC","UC"},0))),MAX($K$4:K12)+1,"")
K14: =IF(AND(UPPER(TRIM($B14))="PR_CULVERT",$A14<>"",ISNUMBER(MATCH(UPPER(TRIM($C14)),{"PC","BC","UC"},0))),MAX($K$4:K13)+1,"")
K15: =IF(AND(UPPER(TRIM($B15))="PR_CULVERT",$A15<>"",ISNUMBER(MATCH(UPPER(TRIM($C15)),{"PC","BC","UC"},0))),MAX($K$4:K14)+1,"")
K16: =IF(AND(UPPER(TRIM($B16))="PR_CULVERT",$A16<>"",ISNUMBER(MATCH(UPPER(TRIM($C16)),{"PC","BC","UC"},0))),MAX($K$4:K15)+1,"")
... K204: =IF(AND(UPPER(TRIM($B204))="PR_CULVERT",$A204<>"",ISNUMBER(MATCH(UPPER(TRIM($C204)),{"PC","BC","UC"},0))),MAX($K$4:K203)+1,"")

Sheet E_Rules
A1: FORM E — TREATMENT RULES (the engineering judgement, written once)
A2: Every stretch on Form C follows the row matching the surface condition recorded for it. Agree these five rows with the design engineer before the survey starts; change one number here and the whole road re-prices. A blank means the item is not done for that condition class.
A4: Condition | B4: What it looks like | C4: Treatment | D4: Sub-base (cm) | E4: Base (cm) | F4: Primer seal | G4: First seal | H4: Second seal
A5: G | B5: Good — shape and camber sound, light maintenance only | C5: BLADE
A6: F | B6: Fair — camber lost in places, some potholing | C6: RESHAPE | D6: 10 | E6: 15 | F6: Y | G6: Y | H6: Y
A7: P | B7: Poor — badly deformed, potholed, camber gone | C7: RESHAPE | D7: 15 | E7: 15 | F7: Y | G7: Y | H7: Y
A8: VP | B8: Very poor — impassable in rain, gravel lost | C8: SCARIFY | D8: 15 | E8: 15 | F8: Y | G8: Y | H8: Y
A9: NR | B9: No road — new alignment or total reconstruction | C9: SCARIFY | D9: 15 | E9: 20 | F9: Y | G9: Y | H9: Y

Sheet F_Road_Data
A1: FORM F — ROAD DATA (the project constants the estimator prices with)
A2: These are the values 00_Project uses — it now READS this sheet, so this is where you change them. A row marked ! is a template figure that has not been confirmed for any particular road: settle those with the design engineer before the bill is issued, because haulage and overhaul alone routinely move a bill by a quarter. Road length, formation width, clearing width and the station count are measured or computed by the workbook and are not set here.
A4: Confirm? | B4: Parameter | C4: Value | D4: Unit | E4: Note | G4: Name
A5: CROSS-SECTION
B6: Carriageway width | C6: 7 | D6: m | G6: P_CW
B7: Shoulder width (one side) | C7: 1 | D7: m | E7: Formation width = CW + 2×SW, computed | G7: P_SW
B8: Existing carriageway width | C8: 4 | D8: m | G8: P_ExtCW
B9: Width for primer seal | C9: 8 | D9: m | G9: P_PrimeW
B10: Width of sealing | C10: 7 | D10: m | G10: P_SealW
A11: PAVEMENT
B12: Sub-base thickness | C12: 0.15 | D12: m | E12: Design thickness; E_Rules sets it per stretch in cm | G12: P_SubbaseT
B13: Base thickness | C13: 0.15 | D13: m | G13: P_BaseT
A14: ! | B14: Overhaul distance, sub-base | C14: 31 | D14: km | E14: Borrow pit to site, less the 1 km free haul | G14: P_OH_Sub
A15: ! | B15: Overhaul distance, base | C15: 40 | D15: km | E15: Quarry to site, less the 1 km free haul | G15: P_OH_Base
A16: SURFACING DESIGN RATES
B17: Primer seal binder rate | C17: 1.4 | D17: l/m² | G17: P_PrimeRate
B18: First seal binder rate | C18: 1.3 | D18: l/m² | G18: P_Seal1Rate
B19: Second seal binder rate | C19: 1.2 | D19: l/m² | G19: P_Seal2Rate
B20: Binder fraction of primer | C20: 0.84 | D20: - | E20: Balance is cutter oil | G20: P_BinderPct
B21: Cutter-oil fraction of primer | C21: 0.16 | D21: - | E21: Binder + cutter must come to 1.00 | G21: P_CutterPct
B22: 10 mm chipping coverage | C22: 120 | D22: m²/m³ | G22: P_Chip10
B23: 14 mm chipping coverage | C23: 100 | D23: m²/m³ | G23: P_Chip14
A24: HAULAGE DISTANCES
A25: ! | B25: Sand (fine aggregate) | C25: 15 | D25: km | G25: P_HaulSand
A26: ! | B26: Coarse aggregate | C26: 25 | D26: km | G26: P_HaulCoarse
A27: ! | B27: Chippings | C27: 60 | D27: km | G27: P_HaulChip
A28: ! | B28: Fill material | C28: 2 | D28: km | G28: P_HaulFill
A29: AGGREGATE YIELD FACTORS
A30: ! | B30: Fine agg. per m³ lean concrete | C30: 0.58 | D30: m³/m³ | E30: C10/40 | G30: P_FineLean
A31: ! | B31: Coarse agg. per m³ lean concrete | C31: 0.92 | D31: m³/m³ | E31: C10/40 | G31: P_CoarseLean
A32: ! | B32: Fine agg. per m³ structural conc. | C32: 0.55 | D32: m³/m³ | E32: C20/20 – C30/20 | G32: P_FineStr
A33: ! | B33: Coarse agg. per m³ struct. conc. | C33: 0.88 | D33: m³/m³ | E33: C20/20 – C30/20 | G33: P_CoarseStr
A34: ROAD FURNITURE
A35: ! | B35: Traffic signs per km (each type) | C35: 10 | D35: nr/km | E35: Three types are billed, so this is ×3 | G35: P_SignsPerKm
A36: ! | B36: STOP line per km | C36: 5 | D36: m/km | G36: P_StopPerKm
A37: ! | B37: Speed ramps per km | C37: 1 | D37: nr/km | G37: P_RampsPerKm
A38: ! | B38: Lane separation line factor | C38: 0.6 | D38: m/m | E38: of sealed length | G38: P_LaneLineF
A39: ! | B39: Centre line factor | C39: 0.4 | D39: m/m | G39: P_CentreLnF
A40: ! | B40: Edge line factor | C40: 2 | D40: m/m | E40: both edges | G40: P_EdgeLnF
A41: ! | B41: Pedestrian crossing factor | C41: 2 | D41: m/km | G41: P_PedXF

Sheet 01_Stations
A1: STATION SCHEDULE — the line diagram, stored as data
A2: One row per 50 m station. Columns D onward are now FORMULAS that resolve the condition survey on Forms A-E — do not type into them. Record the road on those forms instead; this sheet is the result.
A4: Station no. | B4: Chainage from | C4: Chainage | D4: Township | E4: Vegetation | F4: Raise road in low-lying area | G4: Height of fill | H4: Deep gully filling | I4: Cut to widen | J4: Height of cut | K4: Cut width (L+R) | L4: Fill to widen | M4: Height of fill to widen | N4: Fill width (L+R) | O4: Stone pitching | P4: V-ditch left | Q4: V-ditch right | R4: Culvert / drift | S4: Bridge | T4: Conc. U-drain left | U4: U-drain size left | V4: Conc. U-drain right | W4: U-drain size right | X4: Trapezoidal drain left | Y4: Trapezoidal drain right | Z4: Kerb left | AA4: Kerb right | AB4: Scour checks | AC4: Scour check spacing | AD4: Turnout left | AE4: Turnout right | AF4: Retaining wall left | AG4: Retaining wall right | AH4: Blading | AI4: Reshaping | AJ4: Scarifying | AK4: Gravel sub-base | AL4: Gravel base | AM4: Primer seal | AN4: First seal | AO4: Second seal | AQ4: working columns — matched Form C row, then the treatment rule resolved for that stretch
A5: nr | B5: m | D5: 1 | E5: code | F5: 1 | G5: cm | H5: m³ | I5: 1 | J5: cm | K5: m | L5: 1 | M5: cm | N5: m | O5: m² | P5: code | Q5: code | R5: code | S5: code | T5: 1 | U5: cm | V5: 1 | W5: cm | X5: 1 | Y5: 1 | Z5: 1 | AA5: 1 | AB5: 1/2 | AC5: m | AD5: m | AE5: m | AF5: 1 | AG5: 1 | AH5: 1 | AI5: 1 | AJ5: 1 | AK5: cm | AL5: cm | AM5: 1 | AN5: 1 | AO5: 1 | AQ5: C row | AR5: cond | AS5: rule | AT5: treat | AU5: sub | AV5: base | AW5: prime | AX5: seal1 | AY5: seal2
A6: 1 | B6: 0 | C6: 0+000 | D6: =IFERROR(LOOKUP(2,1/((A_Corridor!$A$5:$A$204<>"")*(A_Corridor!$A$5:$A$204<=$B6)*(A_Corridor!$B$5:$B$204>$B6)*(A_Corridor!$C$5:$C$204<>"")),IF(UPPER(A_Corridor!$C$5:$C$204)="Y",1,"")),"") | E6: =IFERROR(LOOKUP(2,1/((A_Corridor!$A$5:$A$204<>"")*(A_Corridor!$A$5:$A$204<=$B6)*(A_Corridor!$B$5:$B$204>$B6)*(A_Corridor!$D$5:$D$204<>"")),IF(A_Corridor!$D$5:$D$204="-","",UPPER(A_Corridor!$D$5:$D$204))),"") | F6: =IFERROR(LOOKUP(2,1/((A_Corridor!$A$5:$A$204<>"")*(A_Corridor!$A$5:$A$204<=$B6)*(A_Corridor!$B$5:$B$204>$B6)*(A_Corridor!$E$5:$E$204<>"")),IF(A_Corridor!$E$5:$E$204="-","",1)),"") | G6: =IFERROR(LOOKUP(2,1/((A_Corridor!$A$5:$A$204<>"")*(A_Corridor!$A$5:$A$204<=$B6)*(A_Corridor!$B$5:$B$204>$B6)*(A_Corridor!$E$5:$E$204<>"")),IF(A_Corridor!$E$5:$E$204="-","",A_Corridor!$E$5:$E$204)),"") | H6: =IFERROR(LOOKUP(2,1/((D_Points!$A$5:$A$204<>"")*(D_Points!$A$5:$A$204>=$B6)*(D_Points!$A$5:$A$204<$B6+P_Interval)*(UPPER(TRIM(D_Points!$B$5:$B$204))="GULLY")*(D_Points!$H$5:$H$204<>"")),D_Points!$H$5:$H$204),"") | I6: =IFERROR(LOOKUP(2,1/((A_Corridor!$A$5:$A$204<>"")*(A_Corridor!$A$5:$A$204<=$B6)*(A_Corridor!$B$5:$B$204>$B6)*(A_Corridor!$F$5:$F$204<>"")),IF(A_Corridor!$F$5:$F$204="-","",1)),"") | J6: =IFERROR(LOOKUP(2,1/((A_Corridor!$A$5:$A$204<>"")*(A_Corridor!$A$5:$A$204<=$B6)*(A_Corridor!$B$5:$B$204>$B6)*(A_Corridor!$F$5:$F$204<>"")),IF(A_Corridor!$F$5:$F$204="-","",A_Corridor!$F$5:$F$204)),"") | K6: =IFERROR(LOOKUP(2,1/((A_Corridor!$A$5:$A$204<>"")*(A_Corridor!$A$5:$A$204<=$B6)*(A_Corridor!$B$5:$B$204>$B6)*(A_Corridor!$G$5:$G$204<>"")),IF(A_Corridor!$G$5:$G$204="-","",A_Corridor!$G$5:$G$204)),"") | L6: =IFERROR(LOOKUP(2,1/((A_Corridor!$A$5:$A$204<>"")*(A_Corridor!$A$5:$A$204<=$B6)*(A_Corridor!$B$5:$B$204>$B6)*(A_Corridor!$H$5:$H$204<>"")),IF(A_Corridor!$H$5:$H$204="-","",1)),"") | M6: =IFERROR(LOOKUP(2,1/((A_Corridor!$A$5:$A$204<>"")*(A_Corridor!$A$5:$A$204<=$B6)*(A_Corridor!$B$5:$B$204>$B6)*(A_Corridor!$H$5:$H$204<>"")),IF(A_Corridor!$H$5:$H$204="-","",A_Corridor!$H$5:$H$204)),"") | N6: =IFERROR(LOOKUP(2,1/((A_Corridor!$A$5:$A$204<>"")*(A_Corridor!$A$5:$A$204<=$B6)*(A_Corridor!$B$5:$B$204>$B6)*(A_Corridor!$I$5:$I$204<>"")),IF(A_Corridor!$I$5:$I$204="-","",A_Corridor!$I$5:$I$204)),"") | O6: =IFERROR(LOOKUP(2,1/((D_Points!$A$5:$A$204<>"")*(D_Points!$A$5:$A$204>=$B6)*(D_Points!$A$5:$A$204<$B6+P_Interval)*(UPPER(TRIM(D_Points!$B$5:$B$204))="PITCHING")*(D_Points!$H$5:$H$204<>"")),D_Points!$H$5:$H$204),"") | P6: =IFERROR(LOOKUP(2,1/((B_Drainage!$A$5:$A$204<>"")*(B_Drainage!$A$5:$A$204<=$B6)*(B_Drainage!$B$5:$B$204>$B6)*(B_Drainage!$C$5:$C$204<>"")),IF(B_Drainage!$C$5:$C$204="-","",UPPER(B_Drainage!$C$5:$C$204))),"") | Q6: =IFERROR(LOOKUP(2,1/((B_Drainage!$A$5:$A$204<>"")*(B_Drainage!$A$5:$A$204<=$B6)*(B_Drainage!$B$5:$B$204>$B6)*(B_Drainage!$D$5:$D$204<>"")),IF(B_Drainage!$D$5:$D$204="-","",UPPER(B_Drainage!$D$5:$D$204))),"") | R6: =IFERROR(LOOKUP(2,1/((D_Points!$A$5:$A$204<>"")*(D_Points!$A$5:$A$204>=$B6)*(D_Points!$A$5:$A$204<$B6+P_Interval)*(RIGHT(UPPER(TRIM(D_Points!$B$5:$B$204)),8)="_CULVERT")),IF(LEFT(UPPER(TRIM(D_Points!$B$5:$B$204)),2)="EX",1,IF(LEFT(UPPER(TRIM(D_Points!$B$5:$B$204)),2)="PR",2,3))),"") | S6: =IFERROR(LOOKUP(2,1/((D_Points!$A$5:$A$204<>"")*(D_Points!$A$5:$A$204>=$B6)*(D_Points!$A$5:$A$204<$B6+P_Interval)*(RIGHT(UPPER(TRIM(D_Points!$B$5:$B$204)),7)="_BRIDGE")),IF(LEFT(UPPER(TRIM(D_Points!$B$5:$B$204)),2)="EX",1,IF(LEFT(UPPER(TRIM(D_Points!$B$5:$B$204)),2)="PR",2,2))),"") | T6: =IFERROR(LOOKUP(2,1/((B_Drainage!$A$5:$A$204<>"")*(B_Drainage!$A$5:$A$204<=$B6)*(B_Drainage!$B$5:$B$204>$B6)*(B_Drainage!$E$5:$E$204<>"")),IF(B_Drainage!$E$5:$E$204="-","",1)),"") | U6: =IFERROR(LOOKUP(2,1/((B_Drainage!$A$5:$A$204<>"")*(B_Drainage!$A$5:$A$204<=$B6)*(B_Drainage!$B$5:$B$204>$B6)*(B_Drainage!$E$5:$E$204<>"")),IF(B_Drainage!$E$5:$E$204="-","",B_Drainage!$E$5:$E$204)),"") | V6: =IFERROR(LOOKUP(2,1/((B_Drainage!$A$5:$A$204<>"")*(B_Drainage!$A$5:$A$204<=$B6)*(B_Drainage!$B$5:$B$204>$B6)*(B_Drainage!$F$5:$F$204<>"")),IF(B_Drainage!$F$5:$F$204="-","",1)),"") | W6: =IFERROR(LOOKUP(2,1/((B_Drainage!$A$5:$A$204<>"")*(B_Drainage!$A$5:$A$204<=$B6)*(B_Drainage!$B$5:$B$204>$B6)*(B_Drainage!$F$5:$F$204<>"")),IF(B_Drainage!$F$5:$F$204="-","",B_Drainage!$F$5:$F$204)),"") | X6: =IFERROR(LOOKUP(2,1/((B_Drainage!$A$5:$A$204<>"")*(B_Drainage!$A$5:$A$204<=$B6)*(B_Drainage!$B$5:$B$204>$B6)*(B_Drainage!$G$5:$G$204<>"")),IF(UPPER(B_Drainage!$G$5:$G$204)="Y",1,"")),"") | Y6: =IFERROR(LOOKUP(2,1/((B_Drainage!$A$5:$A$204<>"")*(B_Drainage!$A$5:$A$204<=$B6)*(B_Drainage!$B$5:$B$204>$B6)*(B_Drainage!$H$5:$H$204<>"")),IF(UPPER(B_Drainage!$H$5:$H$204)="Y",1,"")),"") | Z6: =IFERROR(LOOKUP(2,1/((B_Drainage!$A$5:$A$204<>"")*(B_Drainage!$A$5:$A$204<=$B6)*(B_Drainage!$B$5:$B$204>$B6)*(B_Drainage!$I$5:$I$204<>"")),IF(UPPER(B_Drainage!$I$5:$I$204)="Y",1,"")),"") | AA6: =IFERROR(LOOKUP(2,1/((B_Drainage!$A$5:$A$204<>"")*(B_Drainage!$A$5:$A$204<=$B6)*(B_Drainage!$B$5:$B$204>$B6)*(B_Drainage!$J$5:$J$204<>"")),IF(UPPER(B_Drainage!$J$5:$J$204)="Y",1,"")),"") | AB6: =IFERROR(LOOKUP(2,1/((B_Drainage!$A$5:$A$204<>"")*(B_Drainage!$A$5:$A$204<=$B6)*(B_Drainage!$B$5:$B$204>$B6)*(B_Drainage!$K$5:$K$204<>"")),IF(B_Drainage!$K$5:$K$204="-","",B_Drainage!$K$5:$K$204)),"") | AC6: =IFERROR(LOOKUP(2,1/((B_Drainage!$A$5:$A$204<>"")*(B_Drainage!$A$5:$A$204<=$B6)*(B_Drainage!$B$5:$B$204>$B6)*(B_Drainage!$L$5:$L$204<>"")),IF(B_Drainage!$L$5:$L$204="-","",B_Drainage!$L$5:$L$204)),"") | AD6: =IFERROR(LOOKUP(2,1/((D_Points!$A$5:$A$204<>"")*(D_Points!$A$5:$A$204>=$B6)*(D_Points!$A$5:$A$204<$B6+P_Interval)*(UPPER(TRIM(D_Points!$B$5:$B$204))="TURNOUT_L")*(D_Points!$H$5:$H$204<>"")),D_Points!$H$5:$H$204),"") | AE6: =IFERROR(LOOKUP(2,1/((D_Points!$A$5:$A$204<>"")*(D_Points!$A$5:$A$204>=$B6)*(D_Points!$A$5:$A$204<$B6+P_Interval)*(UPPER(TRIM(D_Points!$B$5:$B$204))="TURNOUT_R")*(D_Points!$H$5:$H$204<>"")),D_Points!$H$5:$H$204),"") | AF6: =IFERROR(LOOKUP(2,1/((B_Drainage!$A$5:$A$204<>"")*(B_Drainage!$A$5:$A$204<=$B6)*(B_Drainage!$B$5:$B$204>$B6)*(B_Drainage!$M$5:$M$204<>"")),IF(UPPER(B_Drainage!$M$5:$M$204)="Y",1,"")),"") | AG6: =IFERROR(LOOKUP(2,1/((B_Drainage!$A$5:$A$204<>"")*(B_Drainage!$A$5:$A$204<=$B6)*(B_Drainage!$B$5:$B$204>$B6)*(B_Drainage!$N$5:$N$204<>"")),IF(UPPER(B_Drainage!$N$5:$N$204)="Y",1,"")),"") | AH6: =IF($AT6="BLADE",1,"") | AI6: =IF($AT6="RESHAPE",1,"") | AJ6: =IF($AT6="SCARIFY",1,"") | AK6: =$AU6 | AL6: =$AV6 | AM6: =IF(OR(UPPER($AW6)="Y",$AW6=1),1,"") | AN6: =IF(OR(UPPER($AX6)="Y",$AX6=1),1,"") | AO6: =IF(OR(UPPER($AY6)="Y",$AY6=1),1,"") | AQ6: =IFERROR(LOOKUP(2,1/((C_Pavement!$A$5:$A$204<>"")*(C_Pavement!$A$5:$A$204<=$B6)*(C_Pavement!$B$5:$B$204>$B6)*(C_Pavement!$C$5:$C$204<>"")),ROW(C_Pavement!$C$5:$C$204)-4),"") | AR6: =IF($AQ6="","",UPPER(TRIM(INDEX(C_Pavement!$C$5:$C$204,$AQ6)))) | AS6: =IF($AR6="","",IFERROR(MATCH($AR6,E_Rules!$A$5:$A$9,0),"")) | AT6: =IF($AQ6="","",IF(INDEX(C_Pavement!$D$5:$D$204,$AQ6)<>"",UPPER(TRIM(INDEX(C_Pavement!$D$5:$D$204,$AQ6))),IF($AS6="","",INDEX(E_Rules!$C$5:$C$9,$AS6)))) | AU6: =IF($AQ6="","",IF(INDEX(C_Pavement!$E$5:$E$204,$AQ6)<>"",IF(INDEX(C_Pavement!$E$5:$E$204,$AQ6)="-","",INDEX(C_Pavement!$E$5:$E$204,$AQ6)),IF($AS6="","",INDEX(E_Rules!$D$5:$D$9,$AS6)))) | AV6: =IF($AQ6="","",IF(INDEX(C_Pavement!$F$5:$F$204,$AQ6)<>"",IF(INDEX(C_Pavement!$F$5:$F$204,$AQ6)="-","",INDEX(C_Pavement!$F$5:$F$204,$AQ6)),IF($AS6="","",INDEX(E_Rules!$E$5:$E$9,$AS6)))) | AW6: =IF($AQ6="","",IF(INDEX(C_Pavement!$G$5:$G$204,$AQ6)<>"",IF(INDEX(C_Pavement!$G$5:$G$204,$AQ6)="-","",INDEX(C_Pavement!$G$5:$G$204,$AQ6)),IF($AS6="","",INDEX(E_Rules!$F$5:$F$9,$AS6)))) | AX6: =IF($AQ6="","",IF(INDEX(C_Pavement!$H$5:$H$204,$AQ6)<>"",IF(INDEX(C_Pavement!$H$5:$H$204,$AQ6)="-","",INDEX(C_Pavement!$H$5:$H$204,$AQ6)),IF($AS6="","",INDEX(E_Rules!$G$5:$G$9,$AS6)))) | AY6: =IF($AQ6="","",IF(INDEX(C_Pavement!$I$5:$I$204,$AQ6)<>"",IF(INDEX(C_Pavement!$I$5:$I$204,$AQ6)="-","",INDEX(C_Pavement!$I$5:$I$204,$AQ6)),IF($AS6="","",INDEX(E_Rules!$H$5:$H$9,$AS6))))
A7: 2 | B7: 50 | C7: 0+050 | D7: =IFERROR(LOOKUP(2,1/((A_Corridor!$A$5:$A$204<>"")*(A_Corridor!$A$5:$A$204<=$B7)*(A_Corridor!$B$5:$B$204>$B7)*(A_Corridor!$C$5:$C$204<>"")),IF(UPPER(A_Corridor!$C$5:$C$204)="Y",1,"")),"") | E7: =IFERROR(LOOKUP(2,1/((A_Corridor!$A$5:$A$204<>"")*(A_Corridor!$A$5:$A$204<=$B7)*(A_Corridor!$B$5:$B$204>$B7)*(A_Corridor!$D$5:$D$204<>"")),IF(A_Corridor!$D$5:$D$204="-","",UPPER(A_Corridor!$D$5:$D$204))),"") | F7: =IFERROR(LOOKUP(2,1/((A_Corridor!$A$5:$A$204<>"")*(A_Corridor!$A$5:$A$204<=$B7)*(A_Corridor!$B$5:$B$204>$B7)*(A_Corridor!$E$5:$E$204<>"")),IF(A_Corridor!$E$5:$E$204="-","",1)),"") | G7: =IFERROR(LOOKUP(2,1/((A_Corridor!$A$5:$A$204<>"")*(A_Corridor!$A$5:$A$204<=$B7)*(A_Corridor!$B$5:$B$204>$B7)*(A_Corridor!$E$5:$E$204<>"")),IF(A_Corridor!$E$5:$E$204="-","",A_Corridor!$E$5:$E$204)),"") | H7: =IFERROR(LOOKUP(2,1/((D_Points!$A$5:$A$204<>"")*(D_Points!$A$5:$A$204>=$B7)*(D_Points!$A$5:$A$204<$B7+P_Interval)*(UPPER(TRIM(D_Points!$B$5:$B$204))="GULLY")*(D_Points!$H$5:$H$204<>"")),D_Points!$H$5:$H$204),"") | I7: =IFERROR(LOOKUP(2,1/((A_Corridor!$A$5:$A$204<>"")*(A_Corridor!$A$5:$A$204<=$B7)*(A_Corridor!$B$5:$B$204>$B7)*(A_Corridor!$F$5:$F$204<>"")),IF(A_Corridor!$F$5:$F$204="-","",1)),"") | J7: =IFERROR(LOOKUP(2,1/((A_Corridor!$A$5:$A$204<>"")*(A_Corridor!$A$5:$A$204<=$B7)*(A_Corridor!$B$5:$B$204>$B7)*(A_Corridor!$F$5:$F$204<>"")),IF(A_Corridor!$F$5:$F$204="-","",A_Corridor!$F$5:$F$204)),"") | K7: =IFERROR(LOOKUP(2,1/((A_Corridor!$A$5:$A$204<>"")*(A_Corridor!$A$5:$A$204<=$B7)*(A_Corridor!$B$5:$B$204>$B7)*(A_Corridor!$G$5:$G$204<>"")),IF(A_Corridor!$G$5:$G$204="-","",A_Corridor!$G$5:$G$204)),"") | L7: =IFERROR(LOOKUP(2,1/((A_Corridor!$A$5:$A$204<>"")*(A_Corridor!$A$5:$A$204<=$B7)*(A_Corridor!$B$5:$B$204>$B7)*(A_Corridor!$H$5:$H$204<>"")),IF(A_Corridor!$H$5:$H$204="-","",1)),"") | M7: =IFERROR(LOOKUP(2,1/((A_Corridor!$A$5:$A$204<>"")*(A_Corridor!$A$5:$A$204<=$B7)*(A_Corridor!$B$5:$B$204>$B7)*(A_Corridor!$H$5:$H$204<>"")),IF(A_Corridor!$H$5:$H$204="-","",A_Corridor!$H$5:$H$204)),"") | N7: =IFERROR(LOOKUP(2,1/((A_Corridor!$A$5:$A$204<>"")*(A_Corridor!$A$5:$A$204<=$B7)*(A_Corridor!$B$5:$B$204>$B7)*(A_Corridor!$I$5:$I$204<>"")),IF(A_Corridor!$I$5:$I$204="-","",A_Corridor!$I$5:$I$204)),"") | O7: =IFERROR(LOOKUP(2,1/((D_Points!$A$5:$A$204<>"")*(D_Points!$A$5:$A$204>=$B7)*(D_Points!$A$5:$A$204<$B7+P_Interval)*(UPPER(TRIM(D_Points!$B$5:$B$204))="PITCHING")*(D_Points!$H$5:$H$204<>"")),D_Points!$H$5:$H$204),"") | P7: =IFERROR(LOOKUP(2,1/((B_Drainage!$A$5:$A$204<>"")*(B_Drainage!$A$5:$A$204<=$B7)*(B_Drainage!$B$5:$B$204>$B7)*(B_Drainage!$C$5:$C$204<>"")),IF(B_Drainage!$C$5:$C$204="-","",UPPER(B_Drainage!$C$5:$C$204))),"") | Q7: =IFERROR(LOOKUP(2,1/((B_Drainage!$A$5:$A$204<>"")*(B_Drainage!$A$5:$A$204<=$B7)*(B_Drainage!$B$5:$B$204>$B7)*(B_Drainage!$D$5:$D$204<>"")),IF(B_Drainage!$D$5:$D$204="-","",UPPER(B_Drainage!$D$5:$D$204))),"") | R7: =IFERROR(LOOKUP(2,1/((D_Points!$A$5:$A$204<>"")*(D_Points!$A$5:$A$204>=$B7)*(D_Points!$A$5:$A$204<$B7+P_Interval)*(RIGHT(UPPER(TRIM(D_Points!$B$5:$B$204)),8)="_CULVERT")),IF(LEFT(UPPER(TRIM(D_Points!$B$5:$B$204)),2)="EX",1,IF(LEFT(UPPER(TRIM(D_Points!$B$5:$B$204)),2)="PR",2,3))),"") | S7: =IFERROR(LOOKUP(2,1/((D_Points!$A$5:$A$204<>"")*(D_Points!$A$5:$A$204>=$B7)*(D_Points!$A$5:$A$204<$B7+P_Interval)*(RIGHT(UPPER(TRIM(D_Points!$B$5:$B$204)),7)="_BRIDGE")),IF(LEFT(UPPER(TRIM(D_Points!$B$5:$B$204)),2)="EX",1,IF(LEFT(UPPER(TRIM(D_Points!$B$5:$B$204)),2)="PR",2,2))),"") | T7: =IFERROR(LOOKUP(2,1/((B_Drainage!$A$5:$A$204<>"")*(B_Drainage!$A$5:$A$204<=$B7)*(B_Drainage!$B$5:$B$204>$B7)*(B_Drainage!$E$5:$E$204<>"")),IF(B_Drainage!$E$5:$E$204="-","",1)),"") | U7: =IFERROR(LOOKUP(2,1/((B_Drainage!$A$5:$A$204<>"")*(B_Drainage!$A$5:$A$204<=$B7)*(B_Drainage!$B$5:$B$204>$B7)*(B_Drainage!$E$5:$E$204<>"")),IF(B_Drainage!$E$5:$E$204="-","",B_Drainage!$E$5:$E$204)),"") | V7: =IFERROR(LOOKUP(2,1/((B_Drainage!$A$5:$A$204<>"")*(B_Drainage!$A$5:$A$204<=$B7)*(B_Drainage!$B$5:$B$204>$B7)*(B_Drainage!$F$5:$F$204<>"")),IF(B_Drainage!$F$5:$F$204="-","",1)),"") | W7: =IFERROR(LOOKUP(2,1/((B_Drainage!$A$5:$A$204<>"")*(B_Drainage!$A$5:$A$204<=$B7)*(B_Drainage!$B$5:$B$204>$B7)*(B_Drainage!$F$5:$F$204<>"")),IF(B_Drainage!$F$5:$F$204="-","",B_Drainage!$F$5:$F$204)),"") | X7: =IFERROR(LOOKUP(2,1/((B_Drainage!$A$5:$A$204<>"")*(B_Drainage!$A$5:$A$204<=$B7)*(B_Drainage!$B$5:$B$204>$B7)*(B_Drainage!$G$5:$G$204<>"")),IF(UPPER(B_Drainage!$G$5:$G$204)="Y",1,"")),"") | Y7: =IFERROR(LOOKUP(2,1/((B_Drainage!$A$5:$A$204<>"")*(B_Drainage!$A$5:$A$204<=$B7)*(B_Drainage!$B$5:$B$204>$B7)*(B_Drainage!$H$5:$H$204<>"")),IF(UPPER(B_Drainage!$H$5:$H$204)="Y",1,"")),"") | Z7: =IFERROR(LOOKUP(2,1/((B_Drainage!$A$5:$A$204<>"")*(B_Drainage!$A$5:$A$204<=$B7)*(B_Drainage!$B$5:$B$204>$B7)*(B_Drainage!$I$5:$I$204<>"")),IF(UPPER(B_Drainage!$I$5:$I$204)="Y",1,"")),"") | AA7: =IFERROR(LOOKUP(2,1/((B_Drainage!$A$5:$A$204<>"")*(B_Drainage!$A$5:$A$204<=$B7)*(B_Drainage!$B$5:$B$204>$B7)*(B_Drainage!$J$5:$J$204<>"")),IF(UPPER(B_Drainage!$J$5:$J$204)="Y",1,"")),"") | AB7: =IFERROR(LOOKUP(2,1/((B_Drainage!$A$5:$A$204<>"")*(B_Drainage!$A$5:$A$204<=$B7)*(B_Drainage!$B$5:$B$204>$B7)*(B_Drainage!$K$5:$K$204<>"")),IF(B_Drainage!$K$5:$K$204="-","",B_Drainage!$K$5:$K$204)),"") | AC7: =IFERROR(LOOKUP(2,1/((B_Drainage!$A$5:$A$204<>"")*(B_Drainage!$A$5:$A$204<=$B7)*(B_Drainage!$B$5:$B$204>$B7)*(B_Drainage!$L$5:$L$204<>"")),IF(B_Drainage!$L$5:$L$204="-","",B_Drainage!$L$5:$L$204)),"") | AD7: =IFERROR(LOOKUP(2,1/((D_Points!$A$5:$A$204<>"")*(D_Points!$A$5:$A$204>=$B7)*(D_Points!$A$5:$A$204<$B7+P_Interval)*(UPPER(TRIM(D_Points!$B$5:$B$204))="TURNOUT_L")*(D_Points!$H$5:$H$204<>"")),D_Points!$H$5:$H$204),"") | AE7: =IFERROR(LOOKUP(2,1/((D_Points!$A$5:$A$204<>"")*(D_Points!$A$5:$A$204>=$B7)*(D_Points!$A$5:$A$204<$B7+P_Interval)*(UPPER(TRIM(D_Points!$B$5:$B$204))="TURNOUT_R")*(D_Points!$H$5:$H$204<>"")),D_Points!$H$5:$H$204),"") | AF7: =IFERROR(LOOKUP(2,1/((B_Drainage!$A$5:$A$204<>"")*(B_Drainage!$A$5:$A$204<=$B7)*(B_Drainage!$B$5:$B$204>$B7)*(B_Drainage!$M$5:$M$204<>"")),IF(UPPER(B_Drainage!$M$5:$M$204)="Y",1,"")),"") | AG7: =IFERROR(LOOKUP(2,1/((B_Drainage!$A$5:$A$204<>"")*(B_Drainage!$A$5:$A$204<=$B7)*(B_Drainage!$B$5:$B$204>$B7)*(B_Drainage!$N$5:$N$204<>"")),IF(UPPER(B_Drainage!$N$5:$N$204)="Y",1,"")),"") | AH7: =IF($AT7="BLADE",1,"") | AI7: =IF($AT7="RESHAPE",1,"") | AJ7: =IF($AT7="SCARIFY",1,"") | AK7: =$AU7 | AL7: =$AV7 | AM7: =IF(OR(UPPER($AW7)="Y",$AW7=1),1,"") | AN7: =IF(OR(UPPER($AX7)="Y",$AX7=1),1,"") | AO7: =IF(OR(UPPER($AY7)="Y",$AY7=1),1,"") | AQ7: =IFERROR(LOOKUP(2,1/((C_Pavement!$A$5:$A$204<>"")*(C_Pavement!$A$5:$A$204<=$B7)*(C_Pavement!$B$5:$B$204>$B7)*(C_Pavement!$C$5:$C$204<>"")),ROW(C_Pavement!$C$5:$C$204)-4),"") | AR7: =IF($AQ7="","",UPPER(TRIM(INDEX(C_Pavement!$C$5:$C$204,$AQ7)))) | AS7: =IF($AR7="","",IFERROR(MATCH($AR7,E_Rules!$A$5:$A$9,0),"")) | AT7: =IF($AQ7="","",IF(INDEX(C_Pavement!$D$5:$D$204,$AQ7)<>"",UPPER(TRIM(INDEX(C_Pavement!$D$5:$D$204,$AQ7))),IF($AS7="","",INDEX(E_Rules!$C$5:$C$9,$AS7)))) | AU7: =IF($AQ7="","",IF(INDEX(C_Pavement!$E$5:$E$204,$AQ7)<>"",IF(INDEX(C_Pavement!$E$5:$E$204,$AQ7)="-","",INDEX(C_Pavement!$E$5:$E$204,$AQ7)),IF($AS7="","",INDEX(E_Rules!$D$5:$D$9,$AS7)))) | AV7: =IF($AQ7="","",IF(INDEX(C_Pavement!$F$5:$F$204,$AQ7)<>"",IF(INDEX(C_Pavement!$F$5:$F$204,$AQ7)="-","",INDEX(C_Pavement!$F$5:$F$204,$AQ7)),IF($AS7="","",INDEX(E_Rules!$E$5:$E$9,$AS7)))) | AW7: =IF($AQ7="","",IF(INDEX(C_Pavement!$G$5:$G$204,$AQ7)<>"",IF(INDEX(C_Pavement!$G$5:$G$204,$AQ7)="-","",INDEX(C_Pavement!$G$5:$G$204,$AQ7)),IF($AS7="","",INDEX(E_Rules!$F$5:$F$9,$AS7)))) | AX7: =IF($AQ7="","",IF(INDEX(C_Pavement!$H$5:$H$204,$AQ7)<>"",IF(INDEX(C_Pavement!$H$5:$H$204,$AQ7)="-","",INDEX(C_Pavement!$H$5:$H$204,$AQ7)),IF($AS7="","",INDEX(E_Rules!$G$5:$G$9,$AS7)))) | AY7: =IF($AQ7="","",IF(INDEX(C_Pavement!$I$5:$I$204,$AQ7)<>"",IF(INDEX(C_Pavement!$I$5:$I$204,$AQ7)="-","",INDEX(C_Pavement!$I$5:$I$204,$AQ7)),IF($AS7="","",INDEX(E_Rules!$H$5:$H$9,$AS7))))
A8: 3 | B8: 100 | C8: 0+100 | D8: =IFERROR(LOOKUP(2,1/((A_Corridor!$A$5:$A$204<>"")*(A_Corridor!$A$5:$A$204<=$B8)*(A_Corridor!$B$5:$B$204>$B8)*(A_Corridor!$C$5:$C$204<>"")),IF(UPPER(A_Corridor!$C$5:$C$204)="Y",1,"")),"") | E8: =IFERROR(LOOKUP(2,1/((A_Corridor!$A$5:$A$204<>"")*(A_Corridor!$A$5:$A$204<=$B8)*(A_Corridor!$B$5:$B$204>$B8)*(A_Corridor!$D$5:$D$204<>"")),IF(A_Corridor!$D$5:$D$204="-","",UPPER(A_Corridor!$D$5:$D$204))),"") | F8: =IFERROR(LOOKUP(2,1/((A_Corridor!$A$5:$A$204<>"")*(A_Corridor!$A$5:$A$204<=$B8)*(A_Corridor!$B$5:$B$204>$B8)*(A_Corridor!$E$5:$E$204<>"")),IF(A_Corridor!$E$5:$E$204="-","",1)),"") | G8: =IFERROR(LOOKUP(2,1/((A_Corridor!$A$5:$A$204<>"")*(A_Corridor!$A$5:$A$204<=$B8)*(A_Corridor!$B$5:$B$204>$B8)*(A_Corridor!$E$5:$E$204<>"")),IF(A_Corridor!$E$5:$E$204="-","",A_Corridor!$E$5:$E$204)),"") | H8: =IFERROR(LOOKUP(2,1/((D_Points!$A$5:$A$204<>"")*(D_Points!$A$5:$A$204>=$B8)*(D_Points!$A$5:$A$204<$B8+P_Interval)*(UPPER(TRIM(D_Points!$B$5:$B$204))="GULLY")*(D_Points!$H$5:$H$204<>"")),D_Points!$H$5:$H$204),"") | I8: =IFERROR(LOOKUP(2,1/((A_Corridor!$A$5:$A$204<>"")*(A_Corridor!$A$5:$A$204<=$B8)*(A_Corridor!$B$5:$B$204>$B8)*(A_Corridor!$F$5:$F$204<>"")),IF(A_Corridor!$F$5:$F$204="-","",1)),"") | J8: =IFERROR(LOOKUP(2,1/((A_Corridor!$A$5:$A$204<>"")*(A_Corridor!$A$5:$A$204<=$B8)*(A_Corridor!$B$5:$B$204>$B8)*(A_Corridor!$F$5:$F$204<>"")),IF(A_Corridor!$F$5:$F$204="-","",A_Corridor!$F$5:$F$204)),"") | K8: =IFERROR(LOOKUP(2,1/((A_Corridor!$A$5:$A$204<>"")*(A_Corridor!$A$5:$A$204<=$B8)*(A_Corridor!$B$5:$B$204>$B8)*(A_Corridor!$G$5:$G$204<>"")),IF(A_Corridor!$G$5:$G$204="-","",A_Corridor!$G$5:$G$204)),"") | L8: =IFERROR(LOOKUP(2,1/((A_Corridor!$A$5:$A$204<>"")*(A_Corridor!$A$5:$A$204<=$B8)*(A_Corridor!$B$5:$B$204>$B8)*(A_Corridor!$H$5:$H$204<>"")),IF(A_Corridor!$H$5:$H$204="-","",1)),"") | M8: =IFERROR(LOOKUP(2,1/((A_Corridor!$A$5:$A$204<>"")*(A_Corridor!$A$5:$A$204<=$B8)*(A_Corridor!$B$5:$B$204>$B8)*(A_Corridor!$H$5:$H$204<>"")),IF(A_Corridor!$H$5:$H$204="-","",A_Corridor!$H$5:$H$204)),"") | N8: =IFERROR(LOOKUP(2,1/((A_Corridor!$A$5:$A$204<>"")*(A_Corridor!$A$5:$A$204<=$B8)*(A_Corridor!$B$5:$B$204>$B8)*(A_Corridor!$I$5:$I$204<>"")),IF(A_Corridor!$I$5:$I$204="-","",A_Corridor!$I$5:$I$204)),"") | O8: =IFERROR(LOOKUP(2,1/((D_Points!$A$5:$A$204<>"")*(D_Points!$A$5:$A$204>=$B8)*(D_Points!$A$5:$A$204<$B8+P_Interval)*(UPPER(TRIM(D_Points!$B$5:$B$204))="PITCHING")*(D_Points!$H$5:$H$204<>"")),D_Points!$H$5:$H$204),"") | P8: =IFERROR(LOOKUP(2,1/((B_Drainage!$A$5:$A$204<>"")*(B_Drainage!$A$5:$A$204<=$B8)*(B_Drainage!$B$5:$B$204>$B8)*(B_Drainage!$C$5:$C$204<>"")),IF(B_Drainage!$C$5:$C$204="-","",UPPER(B_Drainage!$C$5:$C$204))),"") | Q8: =IFERROR(LOOKUP(2,1/((B_Drainage!$A$5:$A$204<>"")*(B_Drainage!$A$5:$A$204<=$B8)*(B_Drainage!$B$5:$B$204>$B8)*(B_Drainage!$D$5:$D$204<>"")),IF(B_Drainage!$D$5:$D$204="-","",UPPER(B_Drainage!$D$5:$D$204))),"") | R8: =IFERROR(LOOKUP(2,1/((D_Points!$A$5:$A$204<>"")*(D_Points!$A$5:$A$204>=$B8)*(D_Points!$A$5:$A$204<$B8+P_Interval)*(RIGHT(UPPER(TRIM(D_Points!$B$5:$B$204)),8)="_CULVERT")),IF(LEFT(UPPER(TRIM(D_Points!$B$5:$B$204)),2)="EX",1,IF(LEFT(UPPER(TRIM(D_Points!$B$5:$B$204)),2)="PR",2,3))),"") | S8: =IFERROR(LOOKUP(2,1/((D_Points!$A$5:$A$204<>"")*(D_Points!$A$5:$A$204>=$B8)*(D_Points!$A$5:$A$204<$B8+P_Interval)*(RIGHT(UPPER(TRIM(D_Points!$B$5:$B$204)),7)="_BRIDGE")),IF(LEFT(UPPER(TRIM(D_Points!$B$5:$B$204)),2)="EX",1,IF(LEFT(UPPER(TRIM(D_Points!$B$5:$B$204)),2)="PR",2,2))),"") | T8: =IFERROR(LOOKUP(2,1/((B_Drainage!$A$5:$A$204<>"")*(B_Drainage!$A$5:$A$204<=$B8)*(B_Drainage!$B$5:$B$204>$B8)*(B_Drainage!$E$5:$E$204<>"")),IF(B_Drainage!$E$5:$E$204="-","",1)),"") | U8: =IFERROR(LOOKUP(2,1/((B_Drainage!$A$5:$A$204<>"")*(B_Drainage!$A$5:$A$204<=$B8)*(B_Drainage!$B$5:$B$204>$B8)*(B_Drainage!$E$5:$E$204<>"")),IF(B_Drainage!$E$5:$E$204="-","",B_Drainage!$E$5:$E$204)),"") | V8: =IFERROR(LOOKUP(2,1/((B_Drainage!$A$5:$A$204<>"")*(B_Drainage!$A$5:$A$204<=$B8)*(B_Drainage!$B$5:$B$204>$B8)*(B_Drainage!$F$5:$F$204<>"")),IF(B_Drainage!$F$5:$F$204="-","",1)),"") | W8: =IFERROR(LOOKUP(2,1/((B_Drainage!$A$5:$A$204<>"")*(B_Drainage!$A$5:$A$204<=$B8)*(B_Drainage!$B$5:$B$204>$B8)*(B_Drainage!$F$5:$F$204<>"")),IF(B_Drainage!$F$5:$F$204="-","",B_Drainage!$F$5:$F$204)),"") | X8: =IFERROR(LOOKUP(2,1/((B_Drainage!$A$5:$A$204<>"")*(B_Drainage!$A$5:$A$204<=$B8)*(B_Drainage!$B$5:$B$204>$B8)*(B_Drainage!$G$5:$G$204<>"")),IF(UPPER(B_Drainage!$G$5:$G$204)="Y",1,"")),"") | Y8: =IFERROR(LOOKUP(2,1/((B_Drainage!$A$5:$A$204<>"")*(B_Drainage!$A$5:$A$204<=$B8)*(B_Drainage!$B$5:$B$204>$B8)*(B_Drainage!$H$5:$H$204<>"")),IF(UPPER(B_Drainage!$H$5:$H$204)="Y",1,"")),"") | Z8: =IFERROR(LOOKUP(2,1/((B_Drainage!$A$5:$A$204<>"")*(B_Drainage!$A$5:$A$204<=$B8)*(B_Drainage!$B$5:$B$204>$B8)*(B_Drainage!$I$5:$I$204<>"")),IF(UPPER(B_Drainage!$I$5:$I$204)="Y",1,"")),"") | AA8: =IFERROR(LOOKUP(2,1/((B_Drainage!$A$5:$A$204<>"")*(B_Drainage!$A$5:$A$204<=$B8)*(B_Drainage!$B$5:$B$204>$B8)*(B_Drainage!$J$5:$J$204<>"")),IF(UPPER(B_Drainage!$J$5:$J$204)="Y",1,"")),"") | AB8: =IFERROR(LOOKUP(2,1/((B_Drainage!$A$5:$A$204<>"")*(B_Drainage!$A$5:$A$204<=$B8)*(B_Drainage!$B$5:$B$204>$B8)*(B_Drainage!$K$5:$K$204<>"")),IF(B_Drainage!$K$5:$K$204="-","",B_Drainage!$K$5:$K$204)),"") | AC8: =IFERROR(LOOKUP(2,1/((B_Drainage!$A$5:$A$204<>"")*(B_Drainage!$A$5:$A$204<=$B8)*(B_Drainage!$B$5:$B$204>$B8)*(B_Drainage!$L$5:$L$204<>"")),IF(B_Drainage!$L$5:$L$204="-","",B_Drainage!$L$5:$L$204)),"") | AD8: =IFERROR(LOOKUP(2,1/((D_Points!$A$5:$A$204<>"")*(D_Points!$A$5:$A$204>=$B8)*(D_Points!$A$5:$A$204<$B8+P_Interval)*(UPPER(TRIM(D_Points!$B$5:$B$204))="TURNOUT_L")*(D_Points!$H$5:$H$204<>"")),D_Points!$H$5:$H$204),"") | AE8: =IFERROR(LOOKUP(2,1/((D_Points!$A$5:$A$204<>"")*(D_Points!$A$5:$A$204>=$B8)*(D_Points!$A$5:$A$204<$B8+P_Interval)*(UPPER(TRIM(D_Points!$B$5:$B$204))="TURNOUT_R")*(D_Points!$H$5:$H$204<>"")),D_Points!$H$5:$H$204),"") | AF8: =IFERROR(LOOKUP(2,1/((B_Drainage!$A$5:$A$204<>"")*(B_Drainage!$A$5:$A$204<=$B8)*(B_Drainage!$B$5:$B$204>$B8)*(B_Drainage!$M$5:$M$204<>"")),IF(UPPER(B_Drainage!$M$5:$M$204)="Y",1,"")),"") | AG8: =IFERROR(LOOKUP(2,1/((B_Drainage!$A$5:$A$204<>"")*(B_Drainage!$A$5:$A$204<=$B8)*(B_Drainage!$B$5:$B$204>$B8)*(B_Drainage!$N$5:$N$204<>"")),IF(UPPER(B_Drainage!$N$5:$N$204)="Y",1,"")),"") | AH8: =IF($AT8="BLADE",1,"") | AI8: =IF($AT8="RESHAPE",1,"") | AJ8: =IF($AT8="SCARIFY",1,"") | AK8: =$AU8 | AL8: =$AV8 | AM8: =IF(OR(UPPER($AW8)="Y",$AW8=1),1,"") | AN8: =IF(OR(UPPER($AX8)="Y",$AX8=1),1,"") | AO8: =IF(OR(UPPER($AY8)="Y",$AY8=1),1,"") | AQ8: =IFERROR(LOOKUP(2,1/((C_Pavement!$A$5:$A$204<>"")*(C_Pavement!$A$5:$A$204<=$B8)*(C_Pavement!$B$5:$B$204>$B8)*(C_Pavement!$C$5:$C$204<>"")),ROW(C_Pavement!$C$5:$C$204)-4),"") | AR8: =IF($AQ8="","",UPPER(TRIM(INDEX(C_Pavement!$C$5:$C$204,$AQ8)))) | AS8: =IF($AR8="","",IFERROR(MATCH($AR8,E_Rules!$A$5:$A$9,0),"")) | AT8: =IF($AQ8="","",IF(INDEX(C_Pavement!$D$5:$D$204,$AQ8)<>"",UPPER(TRIM(INDEX(C_Pavement!$D$5:$D$204,$AQ8))),IF($AS8="","",INDEX(E_Rules!$C$5:$C$9,$AS8)))) | AU8: =IF($AQ8="","",IF(INDEX(C_Pavement!$E$5:$E$204,$AQ8)<>"",IF(INDEX(C_Pavement!$E$5:$E$204,$AQ8)="-","",INDEX(C_Pavement!$E$5:$E$204,$AQ8)),IF($AS8="","",INDEX(E_Rules!$D$5:$D$9,$AS8)))) | AV8: =IF($AQ8="","",IF(INDEX(C_Pavement!$F$5:$F$204,$AQ8)<>"",IF(INDEX(C_Pavement!$F$5:$F$204,$AQ8)="-","",INDEX(C_Pavement!$F$5:$F$204,$AQ8)),IF($AS8="","",INDEX(E_Rules!$E$5:$E$9,$AS8)))) | AW8: =IF($AQ8="","",IF(INDEX(C_Pavement!$G$5:$G$204,$AQ8)<>"",IF(INDEX(C_Pavement!$G$5:$G$204,$AQ8)="-","",INDEX(C_Pavement!$G$5:$G$204,$AQ8)),IF($AS8="","",INDEX(E_Rules!$F$5:$F$9,$AS8)))) | AX8: =IF($AQ8="","",IF(INDEX(C_Pavement!$H$5:$H$204,$AQ8)<>"",IF(INDEX(C_Pavement!$H$5:$H$204,$AQ8)="-","",INDEX(C_Pavement!$H$5:$H$204,$AQ8)),IF($AS8="","",INDEX(E_Rules!$G$5:$G$9,$AS8)))) | AY8: =IF($AQ8="","",IF(INDEX(C_Pavement!$I$5:$I$204,$AQ8)<>"",IF(INDEX(C_Pavement!$I$5:$I$204,$AQ8)="-","",INDEX(C_Pavement!$I$5:$I$204,$AQ8)),IF($AS8="","",INDEX(E_Rules!$H$5:$H$9,$AS8))))
A9: 4 | B9: 150 | C9: 0+150 | D9: =IFERROR(LOOKUP(2,1/((A_Corridor!$A$5:$A$204<>"")*(A_Corridor!$A$5:$A$204<=$B9)*(A_Corridor!$B$5:$B$204>$B9)*(A_Corridor!$C$5:$C$204<>"")),IF(UPPER(A_Corridor!$C$5:$C$204)="Y",1,"")),"") | E9: =IFERROR(LOOKUP(2,1/((A_Corridor!$A$5:$A$204<>"")*(A_Corridor!$A$5:$A$204<=$B9)*(A_Corridor!$B$5:$B$204>$B9)*(A_Corridor!$D$5:$D$204<>"")),IF(A_Corridor!$D$5:$D$204="-","",UPPER(A_Corridor!$D$5:$D$204))),"") | F9: =IFERROR(LOOKUP(2,1/((A_Corridor!$A$5:$A$204<>"")*(A_Corridor!$A$5:$A$204<=$B9)*(A_Corridor!$B$5:$B$204>$B9)*(A_Corridor!$E$5:$E$204<>"")),IF(A_Corridor!$E$5:$E$204="-","",1)),"") | G9: =IFERROR(LOOKUP(2,1/((A_Corridor!$A$5:$A$204<>"")*(A_Corridor!$A$5:$A$204<=$B9)*(A_Corridor!$B$5:$B$204>$B9)*(A_Corridor!$E$5:$E$204<>"")),IF(A_Corridor!$E$5:$E$204="-","",A_Corridor!$E$5:$E$204)),"") | H9: =IFERROR(LOOKUP(2,1/((D_Points!$A$5:$A$204<>"")*(D_Points!$A$5:$A$204>=$B9)*(D_Points!$A$5:$A$204<$B9+P_Interval)*(UPPER(TRIM(D_Points!$B$5:$B$204))="GULLY")*(D_Points!$H$5:$H$204<>"")),D_Points!$H$5:$H$204),"") | I9: =IFERROR(LOOKUP(2,1/((A_Corridor!$A$5:$A$204<>"")*(A_Corridor!$A$5:$A$204<=$B9)*(A_Corridor!$B$5:$B$204>$B9)*(A_Corridor!$F$5:$F$204<>"")),IF(A_Corridor!$F$5:$F$204="-","",1)),"") | J9: =IFERROR(LOOKUP(2,1/((A_Corridor!$A$5:$A$204<>"")*(A_Corridor!$A$5:$A$204<=$B9)*(A_Corridor!$B$5:$B$204>$B9)*(A_Corridor!$F$5:$F$204<>"")),IF(A_Corridor!$F$5:$F$204="-","",A_Corridor!$F$5:$F$204)),"") | K9: =IFERROR(LOOKUP(2,1/((A_Corridor!$A$5:$A$204<>"")*(A_Corridor!$A$5:$A$204<=$B9)*(A_Corridor!$B$5:$B$204>$B9)*(A_Corridor!$G$5:$G$204<>"")),IF(A_Corridor!$G$5:$G$204="-","",A_Corridor!$G$5:$G$204)),"") | L9: =IFERROR(LOOKUP(2,1/((A_Corridor!$A$5:$A$204<>"")*(A_Corridor!$A$5:$A$204<=$B9)*(A_Corridor!$B$5:$B$204>$B9)*(A_Corridor!$H$5:$H$204<>"")),IF(A_Corridor!$H$5:$H$204="-","",1)),"") | M9: =IFERROR(LOOKUP(2,1/((A_Corridor!$A$5:$A$204<>"")*(A_Corridor!$A$5:$A$204<=$B9)*(A_Corridor!$B$5:$B$204>$B9)*(A_Corridor!$H$5:$H$204<>"")),IF(A_Corridor!$H$5:$H$204="-","",A_Corridor!$H$5:$H$204)),"") | N9: =IFERROR(LOOKUP(2,1/((A_Corridor!$A$5:$A$204<>"")*(A_Corridor!$A$5:$A$204<=$B9)*(A_Corridor!$B$5:$B$204>$B9)*(A_Corridor!$I$5:$I$204<>"")),IF(A_Corridor!$I$5:$I$204="-","",A_Corridor!$I$5:$I$204)),"") | O9: =IFERROR(LOOKUP(2,1/((D_Points!$A$5:$A$204<>"")*(D_Points!$A$5:$A$204>=$B9)*(D_Points!$A$5:$A$204<$B9+P_Interval)*(UPPER(TRIM(D_Points!$B$5:$B$204))="PITCHING")*(D_Points!$H$5:$H$204<>"")),D_Points!$H$5:$H$204),"") | P9: =IFERROR(LOOKUP(2,1/((B_Drainage!$A$5:$A$204<>"")*(B_Drainage!$A$5:$A$204<=$B9)*(B_Drainage!$B$5:$B$204>$B9)*(B_Drainage!$C$5:$C$204<>"")),IF(B_Drainage!$C$5:$C$204="-","",UPPER(B_Drainage!$C$5:$C$204))),"") | Q9: =IFERROR(LOOKUP(2,1/((B_Drainage!$A$5:$A$204<>"")*(B_Drainage!$A$5:$A$204<=$B9)*(B_Drainage!$B$5:$B$204>$B9)*(B_Drainage!$D$5:$D$204<>"")),IF(B_Drainage!$D$5:$D$204="-","",UPPER(B_Drainage!$D$5:$D$204))),"") | R9: =IFERROR(LOOKUP(2,1/((D_Points!$A$5:$A$204<>"")*(D_Points!$A$5:$A$204>=$B9)*(D_Points!$A$5:$A$204<$B9+P_Interval)*(RIGHT(UPPER(TRIM(D_Points!$B$5:$B$204)),8)="_CULVERT")),IF(LEFT(UPPER(TRIM(D_Points!$B$5:$B$204)),2)="EX",1,IF(LEFT(UPPER(TRIM(D_Points!$B$5:$B$204)),2)="PR",2,3))),"") | S9: =IFERROR(LOOKUP(2,1/((D_Points!$A$5:$A$204<>"")*(D_Points!$A$5:$A$204>=$B9)*(D_Points!$A$5:$A$204<$B9+P_Interval)*(RIGHT(UPPER(TRIM(D_Points!$B$5:$B$204)),7)="_BRIDGE")),IF(LEFT(UPPER(TRIM(D_Points!$B$5:$B$204)),2)="EX",1,IF(LEFT(UPPER(TRIM(D_Points!$B$5:$B$204)),2)="PR",2,2))),"") | T9: =IFERROR(LOOKUP(2,1/((B_Drainage!$A$5:$A$204<>"")*(B_Drainage!$A$5:$A$204<=$B9)*(B_Drainage!$B$5:$B$204>$B9)*(B_Drainage!$E$5:$E$204<>"")),IF(B_Drainage!$E$5:$E$204="-","",1)),"") | U9: =IFERROR(LOOKUP(2,1/((B_Drainage!$A$5:$A$204<>"")*(B_Drainage!$A$5:$A$204<=$B9)*(B_Drainage!$B$5:$B$204>$B9)*(B_Drainage!$E$5:$E$204<>"")),IF(B_Drainage!$E$5:$E$204="-","",B_Drainage!$E$5:$E$204)),"") | V9: =IFERROR(LOOKUP(2,1/((B_Drainage!$A$5:$A$204<>"")*(B_Drainage!$A$5:$A$204<=$B9)*(B_Drainage!$B$5:$B$204>$B9)*(B_Drainage!$F$5:$F$204<>"")),IF(B_Drainage!$F$5:$F$204="-","",1)),"") | W9: =IFERROR(LOOKUP(2,1/((B_Drainage!$A$5:$A$204<>"")*(B_Drainage!$A$5:$A$204<=$B9)*(B_Drainage!$B$5:$B$204>$B9)*(B_Drainage!$F$5:$F$204<>"")),IF(B_Drainage!$F$5:$F$204="-","",B_Drainage!$F$5:$F$204)),"") | X9: =IFERROR(LOOKUP(2,1/((B_Drainage!$A$5:$A$204<>"")*(B_Drainage!$A$5:$A$204<=$B9)*(B_Drainage!$B$5:$B$204>$B9)*(B_Drainage!$G$5:$G$204<>"")),IF(UPPER(B_Drainage!$G$5:$G$204)="Y",1,"")),"") | Y9: =IFERROR(LOOKUP(2,1/((B_Drainage!$A$5:$A$204<>"")*(B_Drainage!$A$5:$A$204<=$B9)*(B_Drainage!$B$5:$B$204>$B9)*(B_Drainage!$H$5:$H$204<>"")),IF(UPPER(B_Drainage!$H$5:$H$204)="Y",1,"")),"") | Z9: =IFERROR(LOOKUP(2,1/((B_Drainage!$A$5:$A$204<>"")*(B_Drainage!$A$5:$A$204<=$B9)*(B_Drainage!$B$5:$B$204>$B9)*(B_Drainage!$I$5:$I$204<>"")),IF(UPPER(B_Drainage!$I$5:$I$204)="Y",1,"")),"") | AA9: =IFERROR(LOOKUP(2,1/((B_Drainage!$A$5:$A$204<>"")*(B_Drainage!$A$5:$A$204<=$B9)*(B_Drainage!$B$5:$B$204>$B9)*(B_Drainage!$J$5:$J$204<>"")),IF(UPPER(B_Drainage!$J$5:$J$204)="Y",1,"")),"") | AB9: =IFERROR(LOOKUP(2,1/((B_Drainage!$A$5:$A$204<>"")*(B_Drainage!$A$5:$A$204<=$B9)*(B_Drainage!$B$5:$B$204>$B9)*(B_Drainage!$K$5:$K$204<>"")),IF(B_Drainage!$K$5:$K$204="-","",B_Drainage!$K$5:$K$204)),"") | AC9: =IFERROR(LOOKUP(2,1/((B_Drainage!$A$5:$A$204<>"")*(B_Drainage!$A$5:$A$204<=$B9)*(B_Drainage!$B$5:$B$204>$B9)*(B_Drainage!$L$5:$L$204<>"")),IF(B_Drainage!$L$5:$L$204="-","",B_Drainage!$L$5:$L$204)),"") | AD9: =IFERROR(LOOKUP(2,1/((D_Points!$A$5:$A$204<>"")*(D_Points!$A$5:$A$204>=$B9)*(D_Points!$A$5:$A$204<$B9+P_Interval)*(UPPER(TRIM(D_Points!$B$5:$B$204))="TURNOUT_L")*(D_Points!$H$5:$H$204<>"")),D_Points!$H$5:$H$204),"") | AE9: =IFERROR(LOOKUP(2,1/((D_Points!$A$5:$A$204<>"")*(D_Points!$A$5:$A$204>=$B9)*(D_Points!$A$5:$A$204<$B9+P_Interval)*(UPPER(TRIM(D_Points!$B$5:$B$204))="TURNOUT_R")*(D_Points!$H$5:$H$204<>"")),D_Points!$H$5:$H$204),"") | AF9: =IFERROR(LOOKUP(2,1/((B_Drainage!$A$5:$A$204<>"")*(B_Drainage!$A$5:$A$204<=$B9)*(B_Drainage!$B$5:$B$204>$B9)*(B_Drainage!$M$5:$M$204<>"")),IF(UPPER(B_Drainage!$M$5:$M$204)="Y",1,"")),"") | AG9: =IFERROR(LOOKUP(2,1/((B_Drainage!$A$5:$A$204<>"")*(B_Drainage!$A$5:$A$204<=$B9)*(B_Drainage!$B$5:$B$204>$B9)*(B_Drainage!$N$5:$N$204<>"")),IF(UPPER(B_Drainage!$N$5:$N$204)="Y",1,"")),"") | AH9: =IF($AT9="BLADE",1,"") | AI9: =IF($AT9="RESHAPE",1,"") | AJ9: =IF($AT9="SCARIFY",1,"") | AK9: =$AU9 | AL9: =$AV9 | AM9: =IF(OR(UPPER($AW9)="Y",$AW9=1),1,"") | AN9: =IF(OR(UPPER($AX9)="Y",$AX9=1),1,"") | AO9: =IF(OR(UPPER($AY9)="Y",$AY9=1),1,"") | AQ9: =IFERROR(LOOKUP(2,1/((C_Pavement!$A$5:$A$204<>"")*(C_Pavement!$A$5:$A$204<=$B9)*(C_Pavement!$B$5:$B$204>$B9)*(C_Pavement!$C$5:$C$204<>"")),ROW(C_Pavement!$C$5:$C$204)-4),"") | AR9: =IF($AQ9="","",UPPER(TRIM(INDEX(C_Pavement!$C$5:$C$204,$AQ9)))) | AS9: =IF($AR9="","",IFERROR(MATCH($AR9,E_Rules!$A$5:$A$9,0),"")) | AT9: =IF($AQ9="","",IF(INDEX(C_Pavement!$D$5:$D$204,$AQ9)<>"",UPPER(TRIM(INDEX(C_Pavement!$D$5:$D$204,$AQ9))),IF($AS9="","",INDEX(E_Rules!$C$5:$C$9,$AS9)))) | AU9: =IF($AQ9="","",IF(INDEX(C_Pavement!$E$5:$E$204,$AQ9)<>"",IF(INDEX(C_Pavement!$E$5:$E$204,$AQ9)="-","",INDEX(C_Pavement!$E$5:$E$204,$AQ9)),IF($AS9="","",INDEX(E_Rules!$D$5:$D$9,$AS9)))) | AV9: =IF($AQ9="","",IF(INDEX(C_Pavement!$F$5:$F$204,$AQ9)<>"",IF(INDEX(C_Pavement!$F$5:$F$204,$AQ9)="-","",INDEX(C_Pavement!$F$5:$F$204,$AQ9)),IF($AS9="","",INDEX(E_Rules!$E$5:$E$9,$AS9)))) | AW9: =IF($AQ9="","",IF(INDEX(C_Pavement!$G$5:$G$204,$AQ9)<>"",IF(INDEX(C_Pavement!$G$5:$G$204,$AQ9)="-","",INDEX(C_Pavement!$G$5:$G$204,$AQ9)),IF($AS9="","",INDEX(E_Rules!$F$5:$F$9,$AS9)))) | AX9: =IF($AQ9="","",IF(INDEX(C_Pavement!$H$5:$H$204,$AQ9)<>"",IF(INDEX(C_Pavement!$H$5:$H$204,$AQ9)="-","",INDEX(C_Pavement!$H$5:$H$204,$AQ9)),IF($AS9="","",INDEX(E_Rules!$G$5:$G$9,$AS9)))) | AY9: =IF($AQ9="","",IF(INDEX(C_Pavement!$I$5:$I$204,$AQ9)<>"",IF(INDEX(C_Pavement!$I$5:$I$204,$AQ9)="-","",INDEX(C_Pavement!$I$5:$I$204,$AQ9)),IF($AS9="","",INDEX(E_Rules!$H$5:$H$9,$AS9))))
A10: 5 | B10: 200 | C10: 0+200 | D10: =IFERROR(LOOKUP(2,1/((A_Corridor!$A$5:$A$204<>"")*(A_Corridor!$A$5:$A$204<=$B10)*(A_Corridor!$B$5:$B$204>$B10)*(A_Corridor!$C$5:$C$204<>"")),IF(UPPER(A_Corridor!$C$5:$C$204)="Y",1,"")),"") | E10: =IFERROR(LOOKUP(2,1/((A_Corridor!$A$5:$A$204<>"")*(A_Corridor!$A$5:$A$204<=$B10)*(A_Corridor!$B$5:$B$204>$B10)*(A_Corridor!$D$5:$D$204<>"")),IF(A_Corridor!$D$5:$D$204="-","",UPPER(A_Corridor!$D$5:$D$204))),"") | F10: =IFERROR(LOOKUP(2,1/((A_Corridor!$A$5:$A$204<>"")*(A_Corridor!$A$5:$A$204<=$B10)*(A_Corridor!$B$5:$B$204>$B10)*(A_Corridor!$E$5:$E$204<>"")),IF(A_Corridor!$E$5:$E$204="-","",1)),"") | G10: =IFERROR(LOOKUP(2,1/((A_Corridor!$A$5:$A$204<>"")*(A_Corridor!$A$5:$A$204<=$B10)*(A_Corridor!$B$5:$B$204>$B10)*(A_Corridor!$E$5:$E$204<>"")),IF(A_Corridor!$E$5:$E$204="-","",A_Corridor!$E$5:$E$204)),"") | H10: =IFERROR(LOOKUP(2,1/((D_Points!$A$5:$A$204<>"")*(D_Points!$A$5:$A$204>=$B10)*(D_Points!$A$5:$A$204<$B10+P_Interval)*(UPPER(TRIM(D_Points!$B$5:$B$204))="GULLY")*(D_Points!$H$5:$H$204<>"")),D_Points!$H$5:$H$204),"") | I10: =IFERROR(LOOKUP(2,1/((A_Corridor!$A$5:$A$204<>"")*(A_Corridor!$A$5:$A$204<=$B10)*(A_Corridor!$B$5:$B$204>$B10)*(A_Corridor!$F$5:$F$204<>"")),IF(A_Corridor!$F$5:$F$204="-","",1)),"") | J10: =IFERROR(LOOKUP(2,1/((A_Corridor!$A$5:$A$204<>"")*(A_Corridor!$A$5:$A$204<=$B10)*(A_Corridor!$B$5:$B$204>$B10)*(A_Corridor!$F$5:$F$204<>"")),IF(A_Corridor!$F$5:$F$204="-","",A_Corridor!$F$5:$F$204)),"") | K10: =IFERROR(LOOKUP(2,1/((A_Corridor!$A$5:$A$204<>"")*(A_Corridor!$A$5:$A$204<=$B10)*(A_Corridor!$B$5:$B$204>$B10)*(A_Corridor!$G$5:$G$204<>"")),IF(A_Corridor!$G$5:$G$204="-","",A_Corridor!$G$5:$G$204)),"") | L10: =IFERROR(LOOKUP(2,1/((A_Corridor!$A$5:$A$204<>"")*(A_Corridor!$A$5:$A$204<=$B10)*(A_Corridor!$B$5:$B$204>$B10)*(A_Corridor!$H$5:$H$204<>"")),IF(A_Corridor!$H$5:$H$204="-","",1)),"") | M10: =IFERROR(LOOKUP(2,1/((A_Corridor!$A$5:$A$204<>"")*(A_Corridor!$A$5:$A$204<=$B10)*(A_Corridor!$B$5:$B$204>$B10)*(A_Corridor!$H$5:$H$204<>"")),IF(A_Corridor!$H$5:$H$204="-","",A_Corridor!$H$5:$H$204)),"") | N10: =IFERROR(LOOKUP(2,1/((A_Corridor!$A$5:$A$204<>"")*(A_Corridor!$A$5:$A$204<=$B10)*(A_Corridor!$B$5:$B$204>$B10)*(A_Corridor!$I$5:$I$204<>"")),IF(A_Corridor!$I$5:$I$204="-","",A_Corridor!$I$5:$I$204)),"") | O10: =IFERROR(LOOKUP(2,1/((D_Points!$A$5:$A$204<>"")*(D_Points!$A$5:$A$204>=$B10)*(D_Points!$A$5:$A$204<$B10+P_Interval)*(UPPER(TRIM(D_Points!$B$5:$B$204))="PITCHING")*(D_Points!$H$5:$H$204<>"")),D_Points!$H$5:$H$204),"") | P10: =IFERROR(LOOKUP(2,1/((B_Drainage!$A$5:$A$204<>"")*(B_Drainage!$A$5:$A$204<=$B10)*(B_Drainage!$B$5:$B$204>$B10)*(B_Drainage!$C$5:$C$204<>"")),IF(B_Drainage!$C$5:$C$204="-","",UPPER(B_Drainage!$C$5:$C$204))),"") | Q10: =IFERROR(LOOKUP(2,1/((B_Drainage!$A$5:$A$204<>"")*(B_Drainage!$A$5:$A$204<=$B10)*(B_Drainage!$B$5:$B$204>$B10)*(B_Drainage!$D$5:$D$204<>"")),IF(B_Drainage!$D$5:$D$204="-","",UPPER(B_Drainage!$D$5:$D$204))),"") | R10: =IFERROR(LOOKUP(2,1/((D_Points!$A$5:$A$204<>"")*(D_Points!$A$5:$A$204>=$B10)*(D_Points!$A$5:$A$204<$B10+P_Interval)*(RIGHT(UPPER(TRIM(D_Points!$B$5:$B$204)),8)="_CULVERT")),IF(LEFT(UPPER(TRIM(D_Points!$B$5:$B$204)),2)="EX",1,IF(LEFT(UPPER(TRIM(D_Points!$B$5:$B$204)),2)="PR",2,3))),"") | S10: =IFERROR(LOOKUP(2,1/((D_Points!$A$5:$A$204<>"")*(D_Points!$A$5:$A$204>=$B10)*(D_Points!$A$5:$A$204<$B10+P_Interval)*(RIGHT(UPPER(TRIM(D_Points!$B$5:$B$204)),7)="_BRIDGE")),IF(LEFT(UPPER(TRIM(D_Points!$B$5:$B$204)),2)="EX",1,IF(LEFT(UPPER(TRIM(D_Points!$B$5:$B$204)),2)="PR",2,2))),"") | T10: =IFERROR(LOOKUP(2,1/((B_Drainage!$A$5:$A$204<>"")*(B_Drainage!$A$5:$A$204<=$B10)*(B_Drainage!$B$5:$B$204>$B10)*(B_Drainage!$E$5:$E$204<>"")),IF(B_Drainage!$E$5:$E$204="-","",1)),"") | U10: =IFERROR(LOOKUP(2,1/((B_Drainage!$A$5:$A$204<>"")*(B_Drainage!$A$5:$A$204<=$B10)*(B_Drainage!$B$5:$B$204>$B10)*(B_Drainage!$E$5:$E$204<>"")),IF(B_Drainage!$E$5:$E$204="-","",B_Drainage!$E$5:$E$204)),"") | V10: =IFERROR(LOOKUP(2,1/((B_Drainage!$A$5:$A$204<>"")*(B_Drainage!$A$5:$A$204<=$B10)*(B_Drainage!$B$5:$B$204>$B10)*(B_Drainage!$F$5:$F$204<>"")),IF(B_Drainage!$F$5:$F$204="-","",1)),"") | W10: =IFERROR(LOOKUP(2,1/((B_Drainage!$A$5:$A$204<>"")*(B_Drainage!$A$5:$A$204<=$B10)*(B_Drainage!$B$5:$B$204>$B10)*(B_Drainage!$F$5:$F$204<>"")),IF(B_Drainage!$F$5:$F$204="-","",B_Drainage!$F$5:$F$204)),"") | X10: =IFERROR(LOOKUP(2,1/((B_Drainage!$A$5:$A$204<>"")*(B_Drainage!$A$5:$A$204<=$B10)*(B_Drainage!$B$5:$B$204>$B10)*(B_Drainage!$G$5:$G$204<>"")),IF(UPPER(B_Drainage!$G$5:$G$204)="Y",1,"")),"") | Y10: =IFERROR(LOOKUP(2,1/((B_Drainage!$A$5:$A$204<>"")*(B_Drainage!$A$5:$A$204<=$B10)*(B_Drainage!$B$5:$B$204>$B10)*(B_Drainage!$H$5:$H$204<>"")),IF(UPPER(B_Drainage!$H$5:$H$204)="Y",1,"")),"") | Z10: =IFERROR(LOOKUP(2,1/((B_Drainage!$A$5:$A$204<>"")*(B_Drainage!$A$5:$A$204<=$B10)*(B_Drainage!$B$5:$B$204>$B10)*(B_Drainage!$I$5:$I$204<>"")),IF(UPPER(B_Drainage!$I$5:$I$204)="Y",1,"")),"") | AA10: =IFERROR(LOOKUP(2,1/((B_Drainage!$A$5:$A$204<>"")*(B_Drainage!$A$5:$A$204<=$B10)*(B_Drainage!$B$5:$B$204>$B10)*(B_Drainage!$J$5:$J$204<>"")),IF(UPPER(B_Drainage!$J$5:$J$204)="Y",1,"")),"") | AB10: =IFERROR(LOOKUP(2,1/((B_Drainage!$A$5:$A$204<>"")*(B_Drainage!$A$5:$A$204<=$B10)*(B_Drainage!$B$5:$B$204>$B10)*(B_Drainage!$K$5:$K$204<>"")),IF(B_Drainage!$K$5:$K$204="-","",B_Drainage!$K$5:$K$204)),"") | AC10: =IFERROR(LOOKUP(2,1/((B_Drainage!$A$5:$A$204<>"")*(B_Drainage!$A$5:$A$204<=$B10)*(B_Drainage!$B$5:$B$204>$B10)*(B_Drainage!$L$5:$L$204<>"")),IF(B_Drainage!$L$5:$L$204="-","",B_Drainage!$L$5:$L$204)),"") | AD10: =IFERROR(LOOKUP(2,1/((D_Points!$A$5:$A$204<>"")*(D_Points!$A$5:$A$204>=$B10)*(D_Points!$A$5:$A$204<$B10+P_Interval)*(UPPER(TRIM(D_Points!$B$5:$B$204))="TURNOUT_L")*(D_Points!$H$5:$H$204<>"")),D_Points!$H$5:$H$204),"") | AE10: =IFERROR(LOOKUP(2,1/((D_Points!$A$5:$A$204<>"")*(D_Points!$A$5:$A$204>=$B10)*(D_Points!$A$5:$A$204<$B10+P_Interval)*(UPPER(TRIM(D_Points!$B$5:$B$204))="TURNOUT_R")*(D_Points!$H$5:$H$204<>"")),D_Points!$H$5:$H$204),"") | AF10: =IFERROR(LOOKUP(2,1/((B_Drainage!$A$5:$A$204<>"")*(B_Drainage!$A$5:$A$204<=$B10)*(B_Drainage!$B$5:$B$204>$B10)*(B_Drainage!$M$5:$M$204<>"")),IF(UPPER(B_Drainage!$M$5:$M$204)="Y",1,"")),"") | AG10: =IFERROR(LOOKUP(2,1/((B_Drainage!$A$5:$A$204<>"")*(B_Drainage!$A$5:$A$204<=$B10)*(B_Drainage!$B$5:$B$204>$B10)*(B_Drainage!$N$5:$N$204<>"")),IF(UPPER(B_Drainage!$N$5:$N$204)="Y",1,"")),"") | AH10: =IF($AT10="BLADE",1,"") | AI10: =IF($AT10="RESHAPE",1,"") | AJ10: =IF($AT10="SCARIFY",1,"") | AK10: =$AU10 | AL10: =$AV10 | AM10: =IF(OR(UPPER($AW10)="Y",$AW10=1),1,"") | AN10: =IF(OR(UPPER($AX10)="Y",$AX10=1),1,"") | AO10: =IF(OR(UPPER($AY10)="Y",$AY10=1),1,"") | AQ10: =IFERROR(LOOKUP(2,1/((C_Pavement!$A$5:$A$204<>"")*(C_Pavement!$A$5:$A$204<=$B10)*(C_Pavement!$B$5:$B$204>$B10)*(C_Pavement!$C$5:$C$204<>"")),ROW(C_Pavement!$C$5:$C$204)-4),"") | AR10: =IF($AQ10="","",UPPER(TRIM(INDEX(C_Pavement!$C$5:$C$204,$AQ10)))) | AS10: =IF($AR10="","",IFERROR(MATCH($AR10,E_Rules!$A$5:$A$9,0),"")) | AT10: =IF($AQ10="","",IF(INDEX(C_Pavement!$D$5:$D$204,$AQ10)<>"",UPPER(TRIM(INDEX(C_Pavement!$D$5:$D$204,$AQ10))),IF($AS10="","",INDEX(E_Rules!$C$5:$C$9,$AS10)))) | AU10: =IF($AQ10="","",IF(INDEX(C_Pavement!$E$5:$E$204,$AQ10)<>"",IF(INDEX(C_Pavement!$E$5:$E$204,$AQ10)="-","",INDEX(C_Pavement!$E$5:$E$204,$AQ10)),IF($AS10="","",INDEX(E_Rules!$D$5:$D$9,$AS10)))) | AV10: =IF($AQ10="","",IF(INDEX(C_Pavement!$F$5:$F$204,$AQ10)<>"",IF(INDEX(C_Pavement!$F$5:$F$204,$AQ10)="-","",INDEX(C_Pavement!$F$5:$F$204,$AQ10)),IF($AS10="","",INDEX(E_Rules!$E$5:$E$9,$AS10)))) | AW10: =IF($AQ10="","",IF(INDEX(C_Pavement!$G$5:$G$204,$AQ10)<>"",IF(INDEX(C_Pavement!$G$5:$G$204,$AQ10)="-","",INDEX(C_Pavement!$G$5:$G$204,$AQ10)),IF($AS10="","",INDEX(E_Rules!$F$5:$F$9,$AS10)))) | AX10: =IF($AQ10="","",IF(INDEX(C_Pavement!$H$5:$H$204,$AQ10)<>"",IF(INDEX(C_Pavement!$H$5:$H$204,$AQ10)="-","",INDEX(C_Pavement!$H$5:$H$204,$AQ10)),IF($AS10="","",INDEX(E_Rules!$G$5:$G$9,$AS10)))) | AY10: =IF($AQ10="","",IF(INDEX(C_Pavement!$I$5:$I$204,$AQ10)<>"",IF(INDEX(C_Pavement!$I$5:$I$204,$AQ10)="-","",INDEX(C_Pavement!$I$5:$I$204,$AQ10)),IF($AS10="","",INDEX(E_Rules!$H$5:$H$9,$AS10))))
